{
 "cells": [
  {
   "cell_type": "code",
   "execution_count": null,
   "id": "cf5858ae-fe43-404a-8caa-a86342b6c91c",
   "metadata": {},
   "outputs": [],
   "source": [
    "pip install tensorflow"
   ]
  },
  {
   "cell_type": "code",
   "execution_count": 33,
   "id": "cc632cb2",
   "metadata": {},
   "outputs": [
    {
     "name": "stdout",
     "output_type": "stream",
     "text": [
      "GPU available: [PhysicalDevice(name='/physical_device:GPU:0', device_type='GPU'), PhysicalDevice(name='/physical_device:GPU:1', device_type='GPU'), PhysicalDevice(name='/physical_device:GPU:2', device_type='GPU')]\n"
     ]
    }
   ],
   "source": [
    "import numpy as np\n",
    "import pandas as pd\n",
    "import tensorflow as tf\n",
    "import matplotlib.pyplot as plt\n",
    "from sklearn.model_selection import train_test_split\n",
    "from tensorflow.keras.models import Sequential\n",
    "from tensorflow.keras.layers import LSTM, Dense\n",
    "from tensorflow.keras.losses import mse\n",
    "from tensorflow.keras.metrics import RootMeanSquaredError, MeanSquaredError, MeanAbsoluteError\n",
    "from tensorflow.keras.optimizers import Adam\n",
    "from sklearn.preprocessing import MinMaxScaler\n",
    "from sklearn.metrics import r2_score\n",
    "\n",
    "# TensorFlow 로그 메시지 숨기기\n",
    "tf.compat.v1.logging.set_verbosity(tf.compat.v1.logging.ERROR)\n",
    "\n",
    "import tensorflow as tf\n",
    "print(\"GPU available:\", tf.config.list_physical_devices('GPU'))"
   ]
  },
  {
   "cell_type": "code",
   "execution_count": 34,
   "id": "af2ddfec",
   "metadata": {},
   "outputs": [],
   "source": [
    "# 데이터 로드 및 전처리\n",
    "agg_5min = pd.read_csv('aggregation_5min_cpu.csv')\n",
    "\n",
    "# 데이터 스케일링 (Min-Max 스케일링)\n",
    "scaler = MinMaxScaler()\n",
    "agg_5min['CPU rate'] = scaler.fit_transform(agg_5min['CPU rate'].values.reshape(-1, 1))\n",
    "\n",
    "# 슬라이딩 윈도우 설정\n",
    "window_size = 24  # 윈도우 크기 (조정 가능)\n",
    "step_size = 1    # 윈도우 이동 간격 (조정 가능)\n",
    "\n",
    "# 슬라이딩 윈도우를 사용하여 데이터 생성\n",
    "def create_sliding_window_data(data, lookback_time=24, predict_time=1):\n",
    "    X = []\n",
    "    y = []\n",
    "\n",
    "    for i in range(len(data) - (lookback_time - 1) - predict_time):\n",
    "        x_window = data['CPU rate'].iloc[i:i+lookback_time].values\n",
    "        y_value = data['CPU rate'].iloc[i+lookback_time+predict_time-1]\n",
    "\n",
    "        X.append(x_window)\n",
    "        y.append(y_value)\n",
    "\n",
    "    return np.array(X), np.array(y)\n",
    "\n",
    "x, t = create_sliding_window_data(agg_5min)\n",
    "\n",
    "# 데이터 분할 (학습 및 테스트 데이터)\n",
    "x_train, x_test, t_train, t_test = train_test_split(x, t, test_size=0.2, shuffle=False)"
   ]
  },
  {
   "cell_type": "code",
   "execution_count": 35,
   "id": "388cffe6",
   "metadata": {},
   "outputs": [
    {
     "name": "stderr",
     "output_type": "stream",
     "text": [
      "/usr/local/lib/python3.11/dist-packages/keras/src/layers/rnn/rnn.py:200: UserWarning: Do not pass an `input_shape`/`input_dim` argument to a layer. When using Sequential models, prefer using an `Input(shape)` object as the first layer in the model instead.\n",
      "  super().__init__(**kwargs)\n"
     ]
    },
    {
     "data": {
      "text/html": [
       "<pre style=\"white-space:pre;overflow-x:auto;line-height:normal;font-family:Menlo,'DejaVu Sans Mono',consolas,'Courier New',monospace\"><span style=\"font-weight: bold\">Model: \"CPU_LSTM\"</span>\n",
       "</pre>\n"
      ],
      "text/plain": [
       "\u001b[1mModel: \"CPU_LSTM\"\u001b[0m\n"
      ]
     },
     "metadata": {},
     "output_type": "display_data"
    },
    {
     "data": {
      "text/html": [
       "<pre style=\"white-space:pre;overflow-x:auto;line-height:normal;font-family:Menlo,'DejaVu Sans Mono',consolas,'Courier New',monospace\">┏━━━━━━━━━━━━━━━━━━━━━━━━━━━━━━━━━┳━━━━━━━━━━━━━━━━━━━━━━━━┳━━━━━━━━━━━━━━━┓\n",
       "┃<span style=\"font-weight: bold\"> Layer (type)                    </span>┃<span style=\"font-weight: bold\"> Output Shape           </span>┃<span style=\"font-weight: bold\">       Param # </span>┃\n",
       "┡━━━━━━━━━━━━━━━━━━━━━━━━━━━━━━━━━╇━━━━━━━━━━━━━━━━━━━━━━━━╇━━━━━━━━━━━━━━━┩\n",
       "│ lstm_12 (<span style=\"color: #0087ff; text-decoration-color: #0087ff\">LSTM</span>)                  │ (<span style=\"color: #00d7ff; text-decoration-color: #00d7ff\">None</span>, <span style=\"color: #00af00; text-decoration-color: #00af00\">24</span>, <span style=\"color: #00af00; text-decoration-color: #00af00\">128</span>)        │        <span style=\"color: #00af00; text-decoration-color: #00af00\">66,560</span> │\n",
       "├─────────────────────────────────┼────────────────────────┼───────────────┤\n",
       "│ lstm_13 (<span style=\"color: #0087ff; text-decoration-color: #0087ff\">LSTM</span>)                  │ (<span style=\"color: #00d7ff; text-decoration-color: #00d7ff\">None</span>, <span style=\"color: #00af00; text-decoration-color: #00af00\">128</span>)            │       <span style=\"color: #00af00; text-decoration-color: #00af00\">131,584</span> │\n",
       "├─────────────────────────────────┼────────────────────────┼───────────────┤\n",
       "│ dense_6 (<span style=\"color: #0087ff; text-decoration-color: #0087ff\">Dense</span>)                 │ (<span style=\"color: #00d7ff; text-decoration-color: #00d7ff\">None</span>, <span style=\"color: #00af00; text-decoration-color: #00af00\">1</span>)              │           <span style=\"color: #00af00; text-decoration-color: #00af00\">129</span> │\n",
       "└─────────────────────────────────┴────────────────────────┴───────────────┘\n",
       "</pre>\n"
      ],
      "text/plain": [
       "┏━━━━━━━━━━━━━━━━━━━━━━━━━━━━━━━━━┳━━━━━━━━━━━━━━━━━━━━━━━━┳━━━━━━━━━━━━━━━┓\n",
       "┃\u001b[1m \u001b[0m\u001b[1mLayer (type)                   \u001b[0m\u001b[1m \u001b[0m┃\u001b[1m \u001b[0m\u001b[1mOutput Shape          \u001b[0m\u001b[1m \u001b[0m┃\u001b[1m \u001b[0m\u001b[1m      Param #\u001b[0m\u001b[1m \u001b[0m┃\n",
       "┡━━━━━━━━━━━━━━━━━━━━━━━━━━━━━━━━━╇━━━━━━━━━━━━━━━━━━━━━━━━╇━━━━━━━━━━━━━━━┩\n",
       "│ lstm_12 (\u001b[38;5;33mLSTM\u001b[0m)                  │ (\u001b[38;5;45mNone\u001b[0m, \u001b[38;5;34m24\u001b[0m, \u001b[38;5;34m128\u001b[0m)        │        \u001b[38;5;34m66,560\u001b[0m │\n",
       "├─────────────────────────────────┼────────────────────────┼───────────────┤\n",
       "│ lstm_13 (\u001b[38;5;33mLSTM\u001b[0m)                  │ (\u001b[38;5;45mNone\u001b[0m, \u001b[38;5;34m128\u001b[0m)            │       \u001b[38;5;34m131,584\u001b[0m │\n",
       "├─────────────────────────────────┼────────────────────────┼───────────────┤\n",
       "│ dense_6 (\u001b[38;5;33mDense\u001b[0m)                 │ (\u001b[38;5;45mNone\u001b[0m, \u001b[38;5;34m1\u001b[0m)              │           \u001b[38;5;34m129\u001b[0m │\n",
       "└─────────────────────────────────┴────────────────────────┴───────────────┘\n"
      ]
     },
     "metadata": {},
     "output_type": "display_data"
    },
    {
     "data": {
      "text/html": [
       "<pre style=\"white-space:pre;overflow-x:auto;line-height:normal;font-family:Menlo,'DejaVu Sans Mono',consolas,'Courier New',monospace\"><span style=\"font-weight: bold\"> Total params: </span><span style=\"color: #00af00; text-decoration-color: #00af00\">198,273</span> (774.50 KB)\n",
       "</pre>\n"
      ],
      "text/plain": [
       "\u001b[1m Total params: \u001b[0m\u001b[38;5;34m198,273\u001b[0m (774.50 KB)\n"
      ]
     },
     "metadata": {},
     "output_type": "display_data"
    },
    {
     "data": {
      "text/html": [
       "<pre style=\"white-space:pre;overflow-x:auto;line-height:normal;font-family:Menlo,'DejaVu Sans Mono',consolas,'Courier New',monospace\"><span style=\"font-weight: bold\"> Trainable params: </span><span style=\"color: #00af00; text-decoration-color: #00af00\">198,273</span> (774.50 KB)\n",
       "</pre>\n"
      ],
      "text/plain": [
       "\u001b[1m Trainable params: \u001b[0m\u001b[38;5;34m198,273\u001b[0m (774.50 KB)\n"
      ]
     },
     "metadata": {},
     "output_type": "display_data"
    },
    {
     "data": {
      "text/html": [
       "<pre style=\"white-space:pre;overflow-x:auto;line-height:normal;font-family:Menlo,'DejaVu Sans Mono',consolas,'Courier New',monospace\"><span style=\"font-weight: bold\"> Non-trainable params: </span><span style=\"color: #00af00; text-decoration-color: #00af00\">0</span> (0.00 B)\n",
       "</pre>\n"
      ],
      "text/plain": [
       "\u001b[1m Non-trainable params: \u001b[0m\u001b[38;5;34m0\u001b[0m (0.00 B)\n"
      ]
     },
     "metadata": {},
     "output_type": "display_data"
    }
   ],
   "source": [
    "# LSTM 모델 생성\n",
    "cell_size = 128\n",
    "timesteps = 24\n",
    "feature = 1\n",
    "\n",
    "model = Sequential(name=\"CPU_LSTM\")\n",
    "model.add(LSTM(cell_size, input_shape=(timesteps, feature), return_sequences=True))\n",
    "model.add(LSTM(cell_size))\n",
    "model.add(Dense(1))\n",
    "\n",
    "model.compile(loss=mse, optimizer=Adam(learning_rate=0.0001), metrics=[RootMeanSquaredError(), MeanAbsoluteError()])\n",
    "model.summary()"
   ]
  },
  {
   "cell_type": "code",
   "execution_count": 17,
   "id": "2cfa47af",
   "metadata": {},
   "outputs": [
    {
     "name": "stdout",
     "output_type": "stream",
     "text": [
      "Epoch 1/50\n"
     ]
    },
    {
     "name": "stderr",
     "output_type": "stream",
     "text": [
      "E0000 00:00:1735176992.613156   56616 cuda_dnn.cc:522] Loaded runtime CuDNN library: 9.1.0 but source was compiled with: 9.3.0.  CuDNN library needs to have matching major version and equal or higher minor version. If using a binary install, upgrade your CuDNN library.  If building from sources, make sure the library loaded at runtime is compatible with the version specified during compile configuration.\n",
      "2024-12-26 01:36:32.614042: W tensorflow/core/framework/op_kernel.cc:1841] OP_REQUIRES failed at cudnn_rnn_ops.cc:1769 : INVALID_ARGUMENT: Dnn is not supported\n",
      "2024-12-26 01:36:32.614069: I tensorflow/core/framework/local_rendezvous.cc:405] Local rendezvous is aborting with status: INVALID_ARGUMENT: Dnn is not supported\n",
      "\t [[{{function_node __inference_one_step_on_data_7853}}{{node CPU_LSTM_1/lstm_6_1/CudnnRNNV3}}]]\n"
     ]
    },
    {
     "ename": "InvalidArgumentError",
     "evalue": "Graph execution error:\n\nDetected at node CPU_LSTM_1/lstm_6_1/CudnnRNNV3 defined at (most recent call last):\n  File \"/usr/lib/python3.11/runpy.py\", line 198, in _run_module_as_main\n\n  File \"/usr/lib/python3.11/runpy.py\", line 88, in _run_code\n\n  File \"/usr/local/lib/python3.11/dist-packages/ipykernel_launcher.py\", line 18, in <module>\n\n  File \"/usr/local/lib/python3.11/dist-packages/traitlets/config/application.py\", line 1075, in launch_instance\n\n  File \"/usr/local/lib/python3.11/dist-packages/ipykernel/kernelapp.py\", line 739, in start\n\n  File \"/usr/local/lib/python3.11/dist-packages/tornado/platform/asyncio.py\", line 205, in start\n\n  File \"/usr/lib/python3.11/asyncio/base_events.py\", line 604, in run_forever\n\n  File \"/usr/lib/python3.11/asyncio/base_events.py\", line 1909, in _run_once\n\n  File \"/usr/lib/python3.11/asyncio/events.py\", line 80, in _run\n\n  File \"/usr/local/lib/python3.11/dist-packages/ipykernel/kernelbase.py\", line 545, in dispatch_queue\n\n  File \"/usr/local/lib/python3.11/dist-packages/ipykernel/kernelbase.py\", line 534, in process_one\n\n  File \"/usr/local/lib/python3.11/dist-packages/ipykernel/kernelbase.py\", line 437, in dispatch_shell\n\n  File \"/usr/local/lib/python3.11/dist-packages/ipykernel/ipkernel.py\", line 362, in execute_request\n\n  File \"/usr/local/lib/python3.11/dist-packages/ipykernel/kernelbase.py\", line 778, in execute_request\n\n  File \"/usr/local/lib/python3.11/dist-packages/ipykernel/ipkernel.py\", line 449, in do_execute\n\n  File \"/usr/local/lib/python3.11/dist-packages/ipykernel/zmqshell.py\", line 549, in run_cell\n\n  File \"/usr/local/lib/python3.11/dist-packages/IPython/core/interactiveshell.py\", line 3075, in run_cell\n\n  File \"/usr/local/lib/python3.11/dist-packages/IPython/core/interactiveshell.py\", line 3130, in _run_cell\n\n  File \"/usr/local/lib/python3.11/dist-packages/IPython/core/async_helpers.py\", line 128, in _pseudo_sync_runner\n\n  File \"/usr/local/lib/python3.11/dist-packages/IPython/core/interactiveshell.py\", line 3334, in run_cell_async\n\n  File \"/usr/local/lib/python3.11/dist-packages/IPython/core/interactiveshell.py\", line 3517, in run_ast_nodes\n\n  File \"/usr/local/lib/python3.11/dist-packages/IPython/core/interactiveshell.py\", line 3577, in run_code\n\n  File \"/tmp/ipykernel_56249/2685093025.py\", line 2, in <module>\n\n  File \"/usr/local/lib/python3.11/dist-packages/keras/src/utils/traceback_utils.py\", line 117, in error_handler\n\n  File \"/usr/local/lib/python3.11/dist-packages/keras/src/backend/tensorflow/trainer.py\", line 368, in fit\n\n  File \"/usr/local/lib/python3.11/dist-packages/keras/src/backend/tensorflow/trainer.py\", line 216, in function\n\n  File \"/usr/local/lib/python3.11/dist-packages/keras/src/backend/tensorflow/trainer.py\", line 129, in multi_step_on_iterator\n\n  File \"/usr/local/lib/python3.11/dist-packages/keras/src/backend/tensorflow/trainer.py\", line 110, in one_step_on_data\n\n  File \"/usr/local/lib/python3.11/dist-packages/keras/src/backend/tensorflow/trainer.py\", line 56, in train_step\n\n  File \"/usr/local/lib/python3.11/dist-packages/keras/src/utils/traceback_utils.py\", line 117, in error_handler\n\n  File \"/usr/local/lib/python3.11/dist-packages/keras/src/layers/layer.py\", line 899, in __call__\n\n  File \"/usr/local/lib/python3.11/dist-packages/keras/src/utils/traceback_utils.py\", line 117, in error_handler\n\n  File \"/usr/local/lib/python3.11/dist-packages/keras/src/ops/operation.py\", line 46, in __call__\n\n  File \"/usr/local/lib/python3.11/dist-packages/keras/src/utils/traceback_utils.py\", line 156, in error_handler\n\n  File \"/usr/local/lib/python3.11/dist-packages/keras/src/models/sequential.py\", line 213, in call\n\n  File \"/usr/local/lib/python3.11/dist-packages/keras/src/models/functional.py\", line 182, in call\n\n  File \"/usr/local/lib/python3.11/dist-packages/keras/src/ops/function.py\", line 171, in _run_through_graph\n\n  File \"/usr/local/lib/python3.11/dist-packages/keras/src/models/functional.py\", line 632, in call\n\n  File \"/usr/local/lib/python3.11/dist-packages/keras/src/utils/traceback_utils.py\", line 117, in error_handler\n\n  File \"/usr/local/lib/python3.11/dist-packages/keras/src/layers/layer.py\", line 899, in __call__\n\n  File \"/usr/local/lib/python3.11/dist-packages/keras/src/utils/traceback_utils.py\", line 117, in error_handler\n\n  File \"/usr/local/lib/python3.11/dist-packages/keras/src/ops/operation.py\", line 46, in __call__\n\n  File \"/usr/local/lib/python3.11/dist-packages/keras/src/utils/traceback_utils.py\", line 156, in error_handler\n\n  File \"/usr/local/lib/python3.11/dist-packages/keras/src/layers/rnn/lstm.py\", line 570, in call\n\n  File \"/usr/local/lib/python3.11/dist-packages/keras/src/layers/rnn/rnn.py\", line 402, in call\n\n  File \"/usr/local/lib/python3.11/dist-packages/keras/src/layers/rnn/lstm.py\", line 537, in inner_loop\n\n  File \"/usr/local/lib/python3.11/dist-packages/keras/src/backend/tensorflow/rnn.py\", line 841, in lstm\n\n  File \"/usr/local/lib/python3.11/dist-packages/keras/src/backend/tensorflow/rnn.py\", line 933, in _cudnn_lstm\n\nDnn is not supported\n\t [[{{node CPU_LSTM_1/lstm_6_1/CudnnRNNV3}}]] [Op:__inference_multi_step_on_iterator_7923]",
     "output_type": "error",
     "traceback": [
      "\u001b[0;31m---------------------------------------------------------------------------\u001b[0m",
      "\u001b[0;31mInvalidArgumentError\u001b[0m                      Traceback (most recent call last)",
      "Cell \u001b[0;32mIn[17], line 2\u001b[0m\n\u001b[1;32m      1\u001b[0m \u001b[38;5;66;03m# 모델 학습\u001b[39;00m\n\u001b[0;32m----> 2\u001b[0m history \u001b[38;5;241m=\u001b[39m \u001b[43mmodel\u001b[49m\u001b[38;5;241;43m.\u001b[39;49m\u001b[43mfit\u001b[49m\u001b[43m(\u001b[49m\u001b[43mx_train\u001b[49m\u001b[43m,\u001b[49m\u001b[43m \u001b[49m\u001b[43mt_train\u001b[49m\u001b[43m,\u001b[49m\u001b[43m \u001b[49m\u001b[43mepochs\u001b[49m\u001b[38;5;241;43m=\u001b[39;49m\u001b[38;5;241;43m50\u001b[39;49m\u001b[43m,\u001b[49m\u001b[43m \u001b[49m\u001b[43mbatch_size\u001b[49m\u001b[38;5;241;43m=\u001b[39;49m\u001b[38;5;241;43m32\u001b[39;49m\u001b[43m,\u001b[49m\u001b[43m \u001b[49m\u001b[43mvalidation_data\u001b[49m\u001b[38;5;241;43m=\u001b[39;49m\u001b[43m(\u001b[49m\u001b[43mx_test\u001b[49m\u001b[43m,\u001b[49m\u001b[43m \u001b[49m\u001b[43mt_test\u001b[49m\u001b[43m)\u001b[49m\u001b[43m,\u001b[49m\u001b[43m \u001b[49m\u001b[43mverbose\u001b[49m\u001b[38;5;241;43m=\u001b[39;49m\u001b[38;5;241;43m1\u001b[39;49m\u001b[43m)\u001b[49m\n",
      "File \u001b[0;32m/usr/local/lib/python3.11/dist-packages/keras/src/utils/traceback_utils.py:122\u001b[0m, in \u001b[0;36mfilter_traceback.<locals>.error_handler\u001b[0;34m(*args, **kwargs)\u001b[0m\n\u001b[1;32m    119\u001b[0m     filtered_tb \u001b[38;5;241m=\u001b[39m _process_traceback_frames(e\u001b[38;5;241m.\u001b[39m__traceback__)\n\u001b[1;32m    120\u001b[0m     \u001b[38;5;66;03m# To get the full stack trace, call:\u001b[39;00m\n\u001b[1;32m    121\u001b[0m     \u001b[38;5;66;03m# `keras.config.disable_traceback_filtering()`\u001b[39;00m\n\u001b[0;32m--> 122\u001b[0m     \u001b[38;5;28;01mraise\u001b[39;00m e\u001b[38;5;241m.\u001b[39mwith_traceback(filtered_tb) \u001b[38;5;28;01mfrom\u001b[39;00m \u001b[38;5;28;01mNone\u001b[39;00m\n\u001b[1;32m    123\u001b[0m \u001b[38;5;28;01mfinally\u001b[39;00m:\n\u001b[1;32m    124\u001b[0m     \u001b[38;5;28;01mdel\u001b[39;00m filtered_tb\n",
      "File \u001b[0;32m/usr/local/lib/python3.11/dist-packages/tensorflow/python/eager/execute.py:53\u001b[0m, in \u001b[0;36mquick_execute\u001b[0;34m(op_name, num_outputs, inputs, attrs, ctx, name)\u001b[0m\n\u001b[1;32m     51\u001b[0m \u001b[38;5;28;01mtry\u001b[39;00m:\n\u001b[1;32m     52\u001b[0m   ctx\u001b[38;5;241m.\u001b[39mensure_initialized()\n\u001b[0;32m---> 53\u001b[0m   tensors \u001b[38;5;241m=\u001b[39m pywrap_tfe\u001b[38;5;241m.\u001b[39mTFE_Py_Execute(ctx\u001b[38;5;241m.\u001b[39m_handle, device_name, op_name,\n\u001b[1;32m     54\u001b[0m                                       inputs, attrs, num_outputs)\n\u001b[1;32m     55\u001b[0m \u001b[38;5;28;01mexcept\u001b[39;00m core\u001b[38;5;241m.\u001b[39m_NotOkStatusException \u001b[38;5;28;01mas\u001b[39;00m e:\n\u001b[1;32m     56\u001b[0m   \u001b[38;5;28;01mif\u001b[39;00m name \u001b[38;5;129;01mis\u001b[39;00m \u001b[38;5;129;01mnot\u001b[39;00m \u001b[38;5;28;01mNone\u001b[39;00m:\n",
      "\u001b[0;31mInvalidArgumentError\u001b[0m: Graph execution error:\n\nDetected at node CPU_LSTM_1/lstm_6_1/CudnnRNNV3 defined at (most recent call last):\n  File \"/usr/lib/python3.11/runpy.py\", line 198, in _run_module_as_main\n\n  File \"/usr/lib/python3.11/runpy.py\", line 88, in _run_code\n\n  File \"/usr/local/lib/python3.11/dist-packages/ipykernel_launcher.py\", line 18, in <module>\n\n  File \"/usr/local/lib/python3.11/dist-packages/traitlets/config/application.py\", line 1075, in launch_instance\n\n  File \"/usr/local/lib/python3.11/dist-packages/ipykernel/kernelapp.py\", line 739, in start\n\n  File \"/usr/local/lib/python3.11/dist-packages/tornado/platform/asyncio.py\", line 205, in start\n\n  File \"/usr/lib/python3.11/asyncio/base_events.py\", line 604, in run_forever\n\n  File \"/usr/lib/python3.11/asyncio/base_events.py\", line 1909, in _run_once\n\n  File \"/usr/lib/python3.11/asyncio/events.py\", line 80, in _run\n\n  File \"/usr/local/lib/python3.11/dist-packages/ipykernel/kernelbase.py\", line 545, in dispatch_queue\n\n  File \"/usr/local/lib/python3.11/dist-packages/ipykernel/kernelbase.py\", line 534, in process_one\n\n  File \"/usr/local/lib/python3.11/dist-packages/ipykernel/kernelbase.py\", line 437, in dispatch_shell\n\n  File \"/usr/local/lib/python3.11/dist-packages/ipykernel/ipkernel.py\", line 362, in execute_request\n\n  File \"/usr/local/lib/python3.11/dist-packages/ipykernel/kernelbase.py\", line 778, in execute_request\n\n  File \"/usr/local/lib/python3.11/dist-packages/ipykernel/ipkernel.py\", line 449, in do_execute\n\n  File \"/usr/local/lib/python3.11/dist-packages/ipykernel/zmqshell.py\", line 549, in run_cell\n\n  File \"/usr/local/lib/python3.11/dist-packages/IPython/core/interactiveshell.py\", line 3075, in run_cell\n\n  File \"/usr/local/lib/python3.11/dist-packages/IPython/core/interactiveshell.py\", line 3130, in _run_cell\n\n  File \"/usr/local/lib/python3.11/dist-packages/IPython/core/async_helpers.py\", line 128, in _pseudo_sync_runner\n\n  File \"/usr/local/lib/python3.11/dist-packages/IPython/core/interactiveshell.py\", line 3334, in run_cell_async\n\n  File \"/usr/local/lib/python3.11/dist-packages/IPython/core/interactiveshell.py\", line 3517, in run_ast_nodes\n\n  File \"/usr/local/lib/python3.11/dist-packages/IPython/core/interactiveshell.py\", line 3577, in run_code\n\n  File \"/tmp/ipykernel_56249/2685093025.py\", line 2, in <module>\n\n  File \"/usr/local/lib/python3.11/dist-packages/keras/src/utils/traceback_utils.py\", line 117, in error_handler\n\n  File \"/usr/local/lib/python3.11/dist-packages/keras/src/backend/tensorflow/trainer.py\", line 368, in fit\n\n  File \"/usr/local/lib/python3.11/dist-packages/keras/src/backend/tensorflow/trainer.py\", line 216, in function\n\n  File \"/usr/local/lib/python3.11/dist-packages/keras/src/backend/tensorflow/trainer.py\", line 129, in multi_step_on_iterator\n\n  File \"/usr/local/lib/python3.11/dist-packages/keras/src/backend/tensorflow/trainer.py\", line 110, in one_step_on_data\n\n  File \"/usr/local/lib/python3.11/dist-packages/keras/src/backend/tensorflow/trainer.py\", line 56, in train_step\n\n  File \"/usr/local/lib/python3.11/dist-packages/keras/src/utils/traceback_utils.py\", line 117, in error_handler\n\n  File \"/usr/local/lib/python3.11/dist-packages/keras/src/layers/layer.py\", line 899, in __call__\n\n  File \"/usr/local/lib/python3.11/dist-packages/keras/src/utils/traceback_utils.py\", line 117, in error_handler\n\n  File \"/usr/local/lib/python3.11/dist-packages/keras/src/ops/operation.py\", line 46, in __call__\n\n  File \"/usr/local/lib/python3.11/dist-packages/keras/src/utils/traceback_utils.py\", line 156, in error_handler\n\n  File \"/usr/local/lib/python3.11/dist-packages/keras/src/models/sequential.py\", line 213, in call\n\n  File \"/usr/local/lib/python3.11/dist-packages/keras/src/models/functional.py\", line 182, in call\n\n  File \"/usr/local/lib/python3.11/dist-packages/keras/src/ops/function.py\", line 171, in _run_through_graph\n\n  File \"/usr/local/lib/python3.11/dist-packages/keras/src/models/functional.py\", line 632, in call\n\n  File \"/usr/local/lib/python3.11/dist-packages/keras/src/utils/traceback_utils.py\", line 117, in error_handler\n\n  File \"/usr/local/lib/python3.11/dist-packages/keras/src/layers/layer.py\", line 899, in __call__\n\n  File \"/usr/local/lib/python3.11/dist-packages/keras/src/utils/traceback_utils.py\", line 117, in error_handler\n\n  File \"/usr/local/lib/python3.11/dist-packages/keras/src/ops/operation.py\", line 46, in __call__\n\n  File \"/usr/local/lib/python3.11/dist-packages/keras/src/utils/traceback_utils.py\", line 156, in error_handler\n\n  File \"/usr/local/lib/python3.11/dist-packages/keras/src/layers/rnn/lstm.py\", line 570, in call\n\n  File \"/usr/local/lib/python3.11/dist-packages/keras/src/layers/rnn/rnn.py\", line 402, in call\n\n  File \"/usr/local/lib/python3.11/dist-packages/keras/src/layers/rnn/lstm.py\", line 537, in inner_loop\n\n  File \"/usr/local/lib/python3.11/dist-packages/keras/src/backend/tensorflow/rnn.py\", line 841, in lstm\n\n  File \"/usr/local/lib/python3.11/dist-packages/keras/src/backend/tensorflow/rnn.py\", line 933, in _cudnn_lstm\n\nDnn is not supported\n\t [[{{node CPU_LSTM_1/lstm_6_1/CudnnRNNV3}}]] [Op:__inference_multi_step_on_iterator_7923]"
     ]
    }
   ],
   "source": [
    "# 모델 학습\n",
    "history = model.fit(x_train, t_train, epochs=50, batch_size=32, validation_data=(x_test, t_test), verbose=1)"
   ]
  },
  {
   "cell_type": "code",
   "execution_count": 19,
   "id": "b6c07226",
   "metadata": {},
   "outputs": [
    {
     "name": "stderr",
     "output_type": "stream",
     "text": [
      "E0000 00:00:1735177008.494476   56614 cuda_dnn.cc:522] Loaded runtime CuDNN library: 9.1.0 but source was compiled with: 9.3.0.  CuDNN library needs to have matching major version and equal or higher minor version. If using a binary install, upgrade your CuDNN library.  If building from sources, make sure the library loaded at runtime is compatible with the version specified during compile configuration.\n",
      "2024-12-26 01:36:48.495332: W tensorflow/core/framework/op_kernel.cc:1841] OP_REQUIRES failed at cudnn_rnn_ops.cc:1769 : INVALID_ARGUMENT: Dnn is not supported\n"
     ]
    },
    {
     "ename": "InvalidArgumentError",
     "evalue": "Graph execution error:\n\nDetected at node CPU_LSTM_1/lstm_6_1/CudnnRNNV3 defined at (most recent call last):\n  File \"/usr/lib/python3.11/runpy.py\", line 198, in _run_module_as_main\n\n  File \"/usr/lib/python3.11/runpy.py\", line 88, in _run_code\n\n  File \"/usr/local/lib/python3.11/dist-packages/ipykernel_launcher.py\", line 18, in <module>\n\n  File \"/usr/local/lib/python3.11/dist-packages/traitlets/config/application.py\", line 1075, in launch_instance\n\n  File \"/usr/local/lib/python3.11/dist-packages/ipykernel/kernelapp.py\", line 739, in start\n\n  File \"/usr/local/lib/python3.11/dist-packages/tornado/platform/asyncio.py\", line 205, in start\n\n  File \"/usr/lib/python3.11/asyncio/base_events.py\", line 604, in run_forever\n\n  File \"/usr/lib/python3.11/asyncio/base_events.py\", line 1909, in _run_once\n\n  File \"/usr/lib/python3.11/asyncio/events.py\", line 80, in _run\n\n  File \"/usr/local/lib/python3.11/dist-packages/ipykernel/kernelbase.py\", line 545, in dispatch_queue\n\n  File \"/usr/local/lib/python3.11/dist-packages/ipykernel/kernelbase.py\", line 534, in process_one\n\n  File \"/usr/local/lib/python3.11/dist-packages/ipykernel/kernelbase.py\", line 437, in dispatch_shell\n\n  File \"/usr/local/lib/python3.11/dist-packages/ipykernel/ipkernel.py\", line 362, in execute_request\n\n  File \"/usr/local/lib/python3.11/dist-packages/ipykernel/kernelbase.py\", line 778, in execute_request\n\n  File \"/usr/local/lib/python3.11/dist-packages/ipykernel/ipkernel.py\", line 449, in do_execute\n\n  File \"/usr/local/lib/python3.11/dist-packages/ipykernel/zmqshell.py\", line 549, in run_cell\n\n  File \"/usr/local/lib/python3.11/dist-packages/IPython/core/interactiveshell.py\", line 3075, in run_cell\n\n  File \"/usr/local/lib/python3.11/dist-packages/IPython/core/interactiveshell.py\", line 3130, in _run_cell\n\n  File \"/usr/local/lib/python3.11/dist-packages/IPython/core/async_helpers.py\", line 128, in _pseudo_sync_runner\n\n  File \"/usr/local/lib/python3.11/dist-packages/IPython/core/interactiveshell.py\", line 3334, in run_cell_async\n\n  File \"/usr/local/lib/python3.11/dist-packages/IPython/core/interactiveshell.py\", line 3517, in run_ast_nodes\n\n  File \"/usr/local/lib/python3.11/dist-packages/IPython/core/interactiveshell.py\", line 3577, in run_code\n\n  File \"/tmp/ipykernel_56249/2317071419.py\", line 2, in <module>\n\n  File \"/usr/local/lib/python3.11/dist-packages/keras/src/utils/traceback_utils.py\", line 117, in error_handler\n\n  File \"/usr/local/lib/python3.11/dist-packages/keras/src/backend/tensorflow/trainer.py\", line 481, in evaluate\n\n  File \"/usr/local/lib/python3.11/dist-packages/keras/src/backend/tensorflow/trainer.py\", line 216, in function\n\n  File \"/usr/local/lib/python3.11/dist-packages/keras/src/backend/tensorflow/trainer.py\", line 129, in multi_step_on_iterator\n\n  File \"/usr/local/lib/python3.11/dist-packages/keras/src/backend/tensorflow/trainer.py\", line 110, in one_step_on_data\n\n  File \"/usr/local/lib/python3.11/dist-packages/keras/src/backend/tensorflow/trainer.py\", line 87, in test_step\n\n  File \"/usr/local/lib/python3.11/dist-packages/keras/src/utils/traceback_utils.py\", line 117, in error_handler\n\n  File \"/usr/local/lib/python3.11/dist-packages/keras/src/layers/layer.py\", line 899, in __call__\n\n  File \"/usr/local/lib/python3.11/dist-packages/keras/src/utils/traceback_utils.py\", line 117, in error_handler\n\n  File \"/usr/local/lib/python3.11/dist-packages/keras/src/ops/operation.py\", line 46, in __call__\n\n  File \"/usr/local/lib/python3.11/dist-packages/keras/src/utils/traceback_utils.py\", line 156, in error_handler\n\n  File \"/usr/local/lib/python3.11/dist-packages/keras/src/models/sequential.py\", line 213, in call\n\n  File \"/usr/local/lib/python3.11/dist-packages/keras/src/models/functional.py\", line 182, in call\n\n  File \"/usr/local/lib/python3.11/dist-packages/keras/src/ops/function.py\", line 171, in _run_through_graph\n\n  File \"/usr/local/lib/python3.11/dist-packages/keras/src/models/functional.py\", line 632, in call\n\n  File \"/usr/local/lib/python3.11/dist-packages/keras/src/utils/traceback_utils.py\", line 117, in error_handler\n\n  File \"/usr/local/lib/python3.11/dist-packages/keras/src/layers/layer.py\", line 899, in __call__\n\n  File \"/usr/local/lib/python3.11/dist-packages/keras/src/utils/traceback_utils.py\", line 117, in error_handler\n\n  File \"/usr/local/lib/python3.11/dist-packages/keras/src/ops/operation.py\", line 46, in __call__\n\n  File \"/usr/local/lib/python3.11/dist-packages/keras/src/utils/traceback_utils.py\", line 156, in error_handler\n\n  File \"/usr/local/lib/python3.11/dist-packages/keras/src/layers/rnn/lstm.py\", line 570, in call\n\n  File \"/usr/local/lib/python3.11/dist-packages/keras/src/layers/rnn/rnn.py\", line 402, in call\n\n  File \"/usr/local/lib/python3.11/dist-packages/keras/src/layers/rnn/lstm.py\", line 537, in inner_loop\n\n  File \"/usr/local/lib/python3.11/dist-packages/keras/src/backend/tensorflow/rnn.py\", line 841, in lstm\n\n  File \"/usr/local/lib/python3.11/dist-packages/keras/src/backend/tensorflow/rnn.py\", line 933, in _cudnn_lstm\n\nDnn is not supported\n\t [[{{node CPU_LSTM_1/lstm_6_1/CudnnRNNV3}}]] [Op:__inference_multi_step_on_iterator_8342]",
     "output_type": "error",
     "traceback": [
      "\u001b[0;31m---------------------------------------------------------------------------\u001b[0m",
      "\u001b[0;31mInvalidArgumentError\u001b[0m                      Traceback (most recent call last)",
      "Cell \u001b[0;32mIn[19], line 2\u001b[0m\n\u001b[1;32m      1\u001b[0m \u001b[38;5;66;03m# 모델 평가\u001b[39;00m\n\u001b[0;32m----> 2\u001b[0m loss, rmse, mae \u001b[38;5;241m=\u001b[39m \u001b[43mmodel\u001b[49m\u001b[38;5;241;43m.\u001b[39;49m\u001b[43mevaluate\u001b[49m\u001b[43m(\u001b[49m\u001b[43mx_test\u001b[49m\u001b[43m,\u001b[49m\u001b[43m \u001b[49m\u001b[43mt_test\u001b[49m\u001b[43m,\u001b[49m\u001b[43m \u001b[49m\u001b[43mverbose\u001b[49m\u001b[38;5;241;43m=\u001b[39;49m\u001b[38;5;241;43m1\u001b[39;49m\u001b[43m)\u001b[49m\n\u001b[1;32m      3\u001b[0m y_pred \u001b[38;5;241m=\u001b[39m model\u001b[38;5;241m.\u001b[39mpredict(x_test)\n\u001b[1;32m      4\u001b[0m r2 \u001b[38;5;241m=\u001b[39m r2_score(t_test, y_pred)\n",
      "File \u001b[0;32m/usr/local/lib/python3.11/dist-packages/keras/src/utils/traceback_utils.py:122\u001b[0m, in \u001b[0;36mfilter_traceback.<locals>.error_handler\u001b[0;34m(*args, **kwargs)\u001b[0m\n\u001b[1;32m    119\u001b[0m     filtered_tb \u001b[38;5;241m=\u001b[39m _process_traceback_frames(e\u001b[38;5;241m.\u001b[39m__traceback__)\n\u001b[1;32m    120\u001b[0m     \u001b[38;5;66;03m# To get the full stack trace, call:\u001b[39;00m\n\u001b[1;32m    121\u001b[0m     \u001b[38;5;66;03m# `keras.config.disable_traceback_filtering()`\u001b[39;00m\n\u001b[0;32m--> 122\u001b[0m     \u001b[38;5;28;01mraise\u001b[39;00m e\u001b[38;5;241m.\u001b[39mwith_traceback(filtered_tb) \u001b[38;5;28;01mfrom\u001b[39;00m \u001b[38;5;28;01mNone\u001b[39;00m\n\u001b[1;32m    123\u001b[0m \u001b[38;5;28;01mfinally\u001b[39;00m:\n\u001b[1;32m    124\u001b[0m     \u001b[38;5;28;01mdel\u001b[39;00m filtered_tb\n",
      "File \u001b[0;32m/usr/local/lib/python3.11/dist-packages/tensorflow/python/eager/execute.py:53\u001b[0m, in \u001b[0;36mquick_execute\u001b[0;34m(op_name, num_outputs, inputs, attrs, ctx, name)\u001b[0m\n\u001b[1;32m     51\u001b[0m \u001b[38;5;28;01mtry\u001b[39;00m:\n\u001b[1;32m     52\u001b[0m   ctx\u001b[38;5;241m.\u001b[39mensure_initialized()\n\u001b[0;32m---> 53\u001b[0m   tensors \u001b[38;5;241m=\u001b[39m pywrap_tfe\u001b[38;5;241m.\u001b[39mTFE_Py_Execute(ctx\u001b[38;5;241m.\u001b[39m_handle, device_name, op_name,\n\u001b[1;32m     54\u001b[0m                                       inputs, attrs, num_outputs)\n\u001b[1;32m     55\u001b[0m \u001b[38;5;28;01mexcept\u001b[39;00m core\u001b[38;5;241m.\u001b[39m_NotOkStatusException \u001b[38;5;28;01mas\u001b[39;00m e:\n\u001b[1;32m     56\u001b[0m   \u001b[38;5;28;01mif\u001b[39;00m name \u001b[38;5;129;01mis\u001b[39;00m \u001b[38;5;129;01mnot\u001b[39;00m \u001b[38;5;28;01mNone\u001b[39;00m:\n",
      "\u001b[0;31mInvalidArgumentError\u001b[0m: Graph execution error:\n\nDetected at node CPU_LSTM_1/lstm_6_1/CudnnRNNV3 defined at (most recent call last):\n  File \"/usr/lib/python3.11/runpy.py\", line 198, in _run_module_as_main\n\n  File \"/usr/lib/python3.11/runpy.py\", line 88, in _run_code\n\n  File \"/usr/local/lib/python3.11/dist-packages/ipykernel_launcher.py\", line 18, in <module>\n\n  File \"/usr/local/lib/python3.11/dist-packages/traitlets/config/application.py\", line 1075, in launch_instance\n\n  File \"/usr/local/lib/python3.11/dist-packages/ipykernel/kernelapp.py\", line 739, in start\n\n  File \"/usr/local/lib/python3.11/dist-packages/tornado/platform/asyncio.py\", line 205, in start\n\n  File \"/usr/lib/python3.11/asyncio/base_events.py\", line 604, in run_forever\n\n  File \"/usr/lib/python3.11/asyncio/base_events.py\", line 1909, in _run_once\n\n  File \"/usr/lib/python3.11/asyncio/events.py\", line 80, in _run\n\n  File \"/usr/local/lib/python3.11/dist-packages/ipykernel/kernelbase.py\", line 545, in dispatch_queue\n\n  File \"/usr/local/lib/python3.11/dist-packages/ipykernel/kernelbase.py\", line 534, in process_one\n\n  File \"/usr/local/lib/python3.11/dist-packages/ipykernel/kernelbase.py\", line 437, in dispatch_shell\n\n  File \"/usr/local/lib/python3.11/dist-packages/ipykernel/ipkernel.py\", line 362, in execute_request\n\n  File \"/usr/local/lib/python3.11/dist-packages/ipykernel/kernelbase.py\", line 778, in execute_request\n\n  File \"/usr/local/lib/python3.11/dist-packages/ipykernel/ipkernel.py\", line 449, in do_execute\n\n  File \"/usr/local/lib/python3.11/dist-packages/ipykernel/zmqshell.py\", line 549, in run_cell\n\n  File \"/usr/local/lib/python3.11/dist-packages/IPython/core/interactiveshell.py\", line 3075, in run_cell\n\n  File \"/usr/local/lib/python3.11/dist-packages/IPython/core/interactiveshell.py\", line 3130, in _run_cell\n\n  File \"/usr/local/lib/python3.11/dist-packages/IPython/core/async_helpers.py\", line 128, in _pseudo_sync_runner\n\n  File \"/usr/local/lib/python3.11/dist-packages/IPython/core/interactiveshell.py\", line 3334, in run_cell_async\n\n  File \"/usr/local/lib/python3.11/dist-packages/IPython/core/interactiveshell.py\", line 3517, in run_ast_nodes\n\n  File \"/usr/local/lib/python3.11/dist-packages/IPython/core/interactiveshell.py\", line 3577, in run_code\n\n  File \"/tmp/ipykernel_56249/2317071419.py\", line 2, in <module>\n\n  File \"/usr/local/lib/python3.11/dist-packages/keras/src/utils/traceback_utils.py\", line 117, in error_handler\n\n  File \"/usr/local/lib/python3.11/dist-packages/keras/src/backend/tensorflow/trainer.py\", line 481, in evaluate\n\n  File \"/usr/local/lib/python3.11/dist-packages/keras/src/backend/tensorflow/trainer.py\", line 216, in function\n\n  File \"/usr/local/lib/python3.11/dist-packages/keras/src/backend/tensorflow/trainer.py\", line 129, in multi_step_on_iterator\n\n  File \"/usr/local/lib/python3.11/dist-packages/keras/src/backend/tensorflow/trainer.py\", line 110, in one_step_on_data\n\n  File \"/usr/local/lib/python3.11/dist-packages/keras/src/backend/tensorflow/trainer.py\", line 87, in test_step\n\n  File \"/usr/local/lib/python3.11/dist-packages/keras/src/utils/traceback_utils.py\", line 117, in error_handler\n\n  File \"/usr/local/lib/python3.11/dist-packages/keras/src/layers/layer.py\", line 899, in __call__\n\n  File \"/usr/local/lib/python3.11/dist-packages/keras/src/utils/traceback_utils.py\", line 117, in error_handler\n\n  File \"/usr/local/lib/python3.11/dist-packages/keras/src/ops/operation.py\", line 46, in __call__\n\n  File \"/usr/local/lib/python3.11/dist-packages/keras/src/utils/traceback_utils.py\", line 156, in error_handler\n\n  File \"/usr/local/lib/python3.11/dist-packages/keras/src/models/sequential.py\", line 213, in call\n\n  File \"/usr/local/lib/python3.11/dist-packages/keras/src/models/functional.py\", line 182, in call\n\n  File \"/usr/local/lib/python3.11/dist-packages/keras/src/ops/function.py\", line 171, in _run_through_graph\n\n  File \"/usr/local/lib/python3.11/dist-packages/keras/src/models/functional.py\", line 632, in call\n\n  File \"/usr/local/lib/python3.11/dist-packages/keras/src/utils/traceback_utils.py\", line 117, in error_handler\n\n  File \"/usr/local/lib/python3.11/dist-packages/keras/src/layers/layer.py\", line 899, in __call__\n\n  File \"/usr/local/lib/python3.11/dist-packages/keras/src/utils/traceback_utils.py\", line 117, in error_handler\n\n  File \"/usr/local/lib/python3.11/dist-packages/keras/src/ops/operation.py\", line 46, in __call__\n\n  File \"/usr/local/lib/python3.11/dist-packages/keras/src/utils/traceback_utils.py\", line 156, in error_handler\n\n  File \"/usr/local/lib/python3.11/dist-packages/keras/src/layers/rnn/lstm.py\", line 570, in call\n\n  File \"/usr/local/lib/python3.11/dist-packages/keras/src/layers/rnn/rnn.py\", line 402, in call\n\n  File \"/usr/local/lib/python3.11/dist-packages/keras/src/layers/rnn/lstm.py\", line 537, in inner_loop\n\n  File \"/usr/local/lib/python3.11/dist-packages/keras/src/backend/tensorflow/rnn.py\", line 841, in lstm\n\n  File \"/usr/local/lib/python3.11/dist-packages/keras/src/backend/tensorflow/rnn.py\", line 933, in _cudnn_lstm\n\nDnn is not supported\n\t [[{{node CPU_LSTM_1/lstm_6_1/CudnnRNNV3}}]] [Op:__inference_multi_step_on_iterator_8342]"
     ]
    }
   ],
   "source": [
    "# 모델 평가\n",
    "loss, rmse, mae = model.evaluate(x_test, t_test, verbose=1)\n",
    "y_pred = model.predict(x_test)\n",
    "r2 = r2_score(t_test, y_pred)\n",
    "t_test_reset = scaler.inverse_transform(t_test.reshape(-1, 1))  # t_test를 2D 배열로 변환\n",
    "y_pred_reset = scaler.inverse_transform(y_pred)  # y_pred는 이미 2D 배열이므로 추가 변환이 필요 없음\n",
    "\n",
    "mape = np.mean(np.abs((t_test_reset - y_pred_reset) / t_test_reset)) * 100\n",
    "\n",
    "print('Test Loss (MSE):', loss)\n",
    "print('Test RMSE:', rmse)\n",
    "print('Test MAE:', mae)\n",
    "print('R-squared (R^2):', r2)\n",
    "print('Test MAPE:', mape)\n",
    "\n",
    "\n",
    "# 예측 결과 시각화\n",
    "plt.figure(figsize=(12, 6))\n",
    "plt.plot(t_test_reset, label='Actual', color='blue')\n",
    "plt.plot(y_pred_reset, label='Predicted', color='red', linestyle='--')\n",
    "plt.xlabel('Time')\n",
    "plt.ylabel('CPU Rate')\n",
    "plt.title('CPU Rate Prediction')\n",
    "plt.legend()\n",
    "plt.show()"
   ]
  },
  {
   "cell_type": "code",
   "execution_count": 36,
   "id": "822ee4f9",
   "metadata": {},
   "outputs": [
    {
     "name": "stdout",
     "output_type": "stream",
     "text": [
      "1384 1384\n"
     ]
    }
   ],
   "source": [
    "# 데이터 로드 및 전처리\n",
    "agg_10min = pd.read_csv('aggregation_10min_cpu.csv')\n",
    "\n",
    "# 데이터 스케일링 (Min-Max 스케일링)\n",
    "scaler = MinMaxScaler()\n",
    "agg_10min['CPU rate'] = scaler.fit_transform(agg_10min['CPU rate'].values.reshape(-1, 1))\n",
    "\n",
    "# 슬라이딩 윈도우 설정\n",
    "window_size = 24  # 윈도우 크기 (조정 가능)\n",
    "step_size = 3     # 윈도우 이동 간격 (조정 가능)\n",
    "\n",
    "# 슬라이딩 윈도우를 사용하여 데이터 생성\n",
    "def create_sliding_window_data(data, lookback_time=24, predict_time=3):\n",
    "    X = []\n",
    "    y = []\n",
    "\n",
    "    for i in range(0,len(data) - (lookback_time - 1) - predict_time,3):\n",
    "        x_window = data['CPU rate'].iloc[i:i+lookback_time].values\n",
    "        y_value = data['CPU rate'].iloc[i+lookback_time:i+lookback_time+predict_time]\n",
    "\n",
    "        X.append(x_window)\n",
    "        y.append(y_value)\n",
    "\n",
    "    return np.array(X), np.array(y)\n",
    "\n",
    "x_10min, t_10min = create_sliding_window_data(agg_10min)\n",
    "\n",
    "print(len(x_10min), len(t_10min))\n",
    "\n",
    "# 데이터 분할 (학습 및 테스트 데이터)\n",
    "x_train, x_test, t_train, t_test = train_test_split(x_10min, t_10min, test_size=0.2, shuffle=False)"
   ]
  },
  {
   "cell_type": "code",
   "execution_count": 37,
   "id": "1d1eb3e5-7530-4a11-915c-15881bceafd5",
   "metadata": {},
   "outputs": [
    {
     "name": "stderr",
     "output_type": "stream",
     "text": [
      "/usr/local/lib/python3.11/dist-packages/keras/src/layers/rnn/rnn.py:200: UserWarning: Do not pass an `input_shape`/`input_dim` argument to a layer. When using Sequential models, prefer using an `Input(shape)` object as the first layer in the model instead.\n",
      "  super().__init__(**kwargs)\n"
     ]
    },
    {
     "data": {
      "text/html": [
       "<pre style=\"white-space:pre;overflow-x:auto;line-height:normal;font-family:Menlo,'DejaVu Sans Mono',consolas,'Courier New',monospace\"><span style=\"font-weight: bold\">Model: \"CPU_LSTM\"</span>\n",
       "</pre>\n"
      ],
      "text/plain": [
       "\u001b[1mModel: \"CPU_LSTM\"\u001b[0m\n"
      ]
     },
     "metadata": {},
     "output_type": "display_data"
    },
    {
     "data": {
      "text/html": [
       "<pre style=\"white-space:pre;overflow-x:auto;line-height:normal;font-family:Menlo,'DejaVu Sans Mono',consolas,'Courier New',monospace\">┏━━━━━━━━━━━━━━━━━━━━━━━━━━━━━━━━━┳━━━━━━━━━━━━━━━━━━━━━━━━┳━━━━━━━━━━━━━━━┓\n",
       "┃<span style=\"font-weight: bold\"> Layer (type)                    </span>┃<span style=\"font-weight: bold\"> Output Shape           </span>┃<span style=\"font-weight: bold\">       Param # </span>┃\n",
       "┡━━━━━━━━━━━━━━━━━━━━━━━━━━━━━━━━━╇━━━━━━━━━━━━━━━━━━━━━━━━╇━━━━━━━━━━━━━━━┩\n",
       "│ lstm_14 (<span style=\"color: #0087ff; text-decoration-color: #0087ff\">LSTM</span>)                  │ (<span style=\"color: #00d7ff; text-decoration-color: #00d7ff\">None</span>, <span style=\"color: #00af00; text-decoration-color: #00af00\">24</span>, <span style=\"color: #00af00; text-decoration-color: #00af00\">128</span>)        │        <span style=\"color: #00af00; text-decoration-color: #00af00\">66,560</span> │\n",
       "├─────────────────────────────────┼────────────────────────┼───────────────┤\n",
       "│ lstm_15 (<span style=\"color: #0087ff; text-decoration-color: #0087ff\">LSTM</span>)                  │ (<span style=\"color: #00d7ff; text-decoration-color: #00d7ff\">None</span>, <span style=\"color: #00af00; text-decoration-color: #00af00\">128</span>)            │       <span style=\"color: #00af00; text-decoration-color: #00af00\">131,584</span> │\n",
       "├─────────────────────────────────┼────────────────────────┼───────────────┤\n",
       "│ dense_7 (<span style=\"color: #0087ff; text-decoration-color: #0087ff\">Dense</span>)                 │ (<span style=\"color: #00d7ff; text-decoration-color: #00d7ff\">None</span>, <span style=\"color: #00af00; text-decoration-color: #00af00\">1</span>)              │           <span style=\"color: #00af00; text-decoration-color: #00af00\">129</span> │\n",
       "└─────────────────────────────────┴────────────────────────┴───────────────┘\n",
       "</pre>\n"
      ],
      "text/plain": [
       "┏━━━━━━━━━━━━━━━━━━━━━━━━━━━━━━━━━┳━━━━━━━━━━━━━━━━━━━━━━━━┳━━━━━━━━━━━━━━━┓\n",
       "┃\u001b[1m \u001b[0m\u001b[1mLayer (type)                   \u001b[0m\u001b[1m \u001b[0m┃\u001b[1m \u001b[0m\u001b[1mOutput Shape          \u001b[0m\u001b[1m \u001b[0m┃\u001b[1m \u001b[0m\u001b[1m      Param #\u001b[0m\u001b[1m \u001b[0m┃\n",
       "┡━━━━━━━━━━━━━━━━━━━━━━━━━━━━━━━━━╇━━━━━━━━━━━━━━━━━━━━━━━━╇━━━━━━━━━━━━━━━┩\n",
       "│ lstm_14 (\u001b[38;5;33mLSTM\u001b[0m)                  │ (\u001b[38;5;45mNone\u001b[0m, \u001b[38;5;34m24\u001b[0m, \u001b[38;5;34m128\u001b[0m)        │        \u001b[38;5;34m66,560\u001b[0m │\n",
       "├─────────────────────────────────┼────────────────────────┼───────────────┤\n",
       "│ lstm_15 (\u001b[38;5;33mLSTM\u001b[0m)                  │ (\u001b[38;5;45mNone\u001b[0m, \u001b[38;5;34m128\u001b[0m)            │       \u001b[38;5;34m131,584\u001b[0m │\n",
       "├─────────────────────────────────┼────────────────────────┼───────────────┤\n",
       "│ dense_7 (\u001b[38;5;33mDense\u001b[0m)                 │ (\u001b[38;5;45mNone\u001b[0m, \u001b[38;5;34m1\u001b[0m)              │           \u001b[38;5;34m129\u001b[0m │\n",
       "└─────────────────────────────────┴────────────────────────┴───────────────┘\n"
      ]
     },
     "metadata": {},
     "output_type": "display_data"
    },
    {
     "data": {
      "text/html": [
       "<pre style=\"white-space:pre;overflow-x:auto;line-height:normal;font-family:Menlo,'DejaVu Sans Mono',consolas,'Courier New',monospace\"><span style=\"font-weight: bold\"> Total params: </span><span style=\"color: #00af00; text-decoration-color: #00af00\">198,273</span> (774.50 KB)\n",
       "</pre>\n"
      ],
      "text/plain": [
       "\u001b[1m Total params: \u001b[0m\u001b[38;5;34m198,273\u001b[0m (774.50 KB)\n"
      ]
     },
     "metadata": {},
     "output_type": "display_data"
    },
    {
     "data": {
      "text/html": [
       "<pre style=\"white-space:pre;overflow-x:auto;line-height:normal;font-family:Menlo,'DejaVu Sans Mono',consolas,'Courier New',monospace\"><span style=\"font-weight: bold\"> Trainable params: </span><span style=\"color: #00af00; text-decoration-color: #00af00\">198,273</span> (774.50 KB)\n",
       "</pre>\n"
      ],
      "text/plain": [
       "\u001b[1m Trainable params: \u001b[0m\u001b[38;5;34m198,273\u001b[0m (774.50 KB)\n"
      ]
     },
     "metadata": {},
     "output_type": "display_data"
    },
    {
     "data": {
      "text/html": [
       "<pre style=\"white-space:pre;overflow-x:auto;line-height:normal;font-family:Menlo,'DejaVu Sans Mono',consolas,'Courier New',monospace\"><span style=\"font-weight: bold\"> Non-trainable params: </span><span style=\"color: #00af00; text-decoration-color: #00af00\">0</span> (0.00 B)\n",
       "</pre>\n"
      ],
      "text/plain": [
       "\u001b[1m Non-trainable params: \u001b[0m\u001b[38;5;34m0\u001b[0m (0.00 B)\n"
      ]
     },
     "metadata": {},
     "output_type": "display_data"
    }
   ],
   "source": [
    "# aggregation_10min LSTM 모델 생성\n",
    "cell_size = 128\n",
    "timesteps = 24\n",
    "feature = 1\n",
    "\n",
    "model = Sequential(name=\"CPU_LSTM\")\n",
    "model.add(LSTM(cell_size, input_shape=(timesteps, feature), return_sequences=True))\n",
    "model.add(LSTM(cell_size))\n",
    "model.add(Dense(1))\n",
    "\n",
    "model.compile(loss=mse, optimizer=Adam(learning_rate=0.0001), metrics=[RootMeanSquaredError(), MeanAbsoluteError()])\n",
    "model.summary()"
   ]
  },
  {
   "cell_type": "code",
   "execution_count": 38,
   "id": "a276d288-9d5d-4aa2-b9d1-cf8f29e5ff74",
   "metadata": {},
   "outputs": [
    {
     "name": "stdout",
     "output_type": "stream",
     "text": [
      "TensorFlow version: 2.18.0\n",
      "GPU available: [PhysicalDevice(name='/physical_device:GPU:0', device_type='GPU'), PhysicalDevice(name='/physical_device:GPU:1', device_type='GPU'), PhysicalDevice(name='/physical_device:GPU:2', device_type='GPU')]\n"
     ]
    }
   ],
   "source": [
    "import tensorflow as tf\n",
    "print(\"TensorFlow version:\", tf.__version__)\n",
    "print(\"GPU available:\", tf.config.list_physical_devices('GPU'))"
   ]
  },
  {
   "cell_type": "code",
   "execution_count": 39,
   "id": "97b60816-d4a8-4838-816b-88f0fbeee214",
   "metadata": {},
   "outputs": [
    {
     "name": "stdout",
     "output_type": "stream",
     "text": [
      "Epoch 1/50\n"
     ]
    },
    {
     "name": "stderr",
     "output_type": "stream",
     "text": [
      "E0000 00:00:1735177615.600958   56614 cuda_dnn.cc:522] Loaded runtime CuDNN library: 9.1.0 but source was compiled with: 9.3.0.  CuDNN library needs to have matching major version and equal or higher minor version. If using a binary install, upgrade your CuDNN library.  If building from sources, make sure the library loaded at runtime is compatible with the version specified during compile configuration.\n",
      "2024-12-26 01:46:55.601858: W tensorflow/core/framework/op_kernel.cc:1841] OP_REQUIRES failed at cudnn_rnn_ops.cc:1769 : INVALID_ARGUMENT: Dnn is not supported\n"
     ]
    },
    {
     "ename": "InvalidArgumentError",
     "evalue": "Graph execution error:\n\nDetected at node CPU_LSTM_1/lstm_14_1/CudnnRNNV3 defined at (most recent call last):\n  File \"/usr/lib/python3.11/runpy.py\", line 198, in _run_module_as_main\n\n  File \"/usr/lib/python3.11/runpy.py\", line 88, in _run_code\n\n  File \"/usr/local/lib/python3.11/dist-packages/ipykernel_launcher.py\", line 18, in <module>\n\n  File \"/usr/local/lib/python3.11/dist-packages/traitlets/config/application.py\", line 1075, in launch_instance\n\n  File \"/usr/local/lib/python3.11/dist-packages/ipykernel/kernelapp.py\", line 739, in start\n\n  File \"/usr/local/lib/python3.11/dist-packages/tornado/platform/asyncio.py\", line 205, in start\n\n  File \"/usr/lib/python3.11/asyncio/base_events.py\", line 604, in run_forever\n\n  File \"/usr/lib/python3.11/asyncio/base_events.py\", line 1909, in _run_once\n\n  File \"/usr/lib/python3.11/asyncio/events.py\", line 80, in _run\n\n  File \"/usr/local/lib/python3.11/dist-packages/ipykernel/kernelbase.py\", line 545, in dispatch_queue\n\n  File \"/usr/local/lib/python3.11/dist-packages/ipykernel/kernelbase.py\", line 534, in process_one\n\n  File \"/usr/local/lib/python3.11/dist-packages/ipykernel/kernelbase.py\", line 437, in dispatch_shell\n\n  File \"/usr/local/lib/python3.11/dist-packages/ipykernel/ipkernel.py\", line 362, in execute_request\n\n  File \"/usr/local/lib/python3.11/dist-packages/ipykernel/kernelbase.py\", line 778, in execute_request\n\n  File \"/usr/local/lib/python3.11/dist-packages/ipykernel/ipkernel.py\", line 449, in do_execute\n\n  File \"/usr/local/lib/python3.11/dist-packages/ipykernel/zmqshell.py\", line 549, in run_cell\n\n  File \"/usr/local/lib/python3.11/dist-packages/IPython/core/interactiveshell.py\", line 3075, in run_cell\n\n  File \"/usr/local/lib/python3.11/dist-packages/IPython/core/interactiveshell.py\", line 3130, in _run_cell\n\n  File \"/usr/local/lib/python3.11/dist-packages/IPython/core/async_helpers.py\", line 128, in _pseudo_sync_runner\n\n  File \"/usr/local/lib/python3.11/dist-packages/IPython/core/interactiveshell.py\", line 3334, in run_cell_async\n\n  File \"/usr/local/lib/python3.11/dist-packages/IPython/core/interactiveshell.py\", line 3517, in run_ast_nodes\n\n  File \"/usr/local/lib/python3.11/dist-packages/IPython/core/interactiveshell.py\", line 3577, in run_code\n\n  File \"/tmp/ipykernel_56249/2685093025.py\", line 2, in <module>\n\n  File \"/usr/local/lib/python3.11/dist-packages/keras/src/utils/traceback_utils.py\", line 117, in error_handler\n\n  File \"/usr/local/lib/python3.11/dist-packages/keras/src/backend/tensorflow/trainer.py\", line 368, in fit\n\n  File \"/usr/local/lib/python3.11/dist-packages/keras/src/backend/tensorflow/trainer.py\", line 216, in function\n\n  File \"/usr/local/lib/python3.11/dist-packages/keras/src/backend/tensorflow/trainer.py\", line 129, in multi_step_on_iterator\n\n  File \"/usr/local/lib/python3.11/dist-packages/keras/src/backend/tensorflow/trainer.py\", line 110, in one_step_on_data\n\n  File \"/usr/local/lib/python3.11/dist-packages/keras/src/backend/tensorflow/trainer.py\", line 56, in train_step\n\n  File \"/usr/local/lib/python3.11/dist-packages/keras/src/utils/traceback_utils.py\", line 117, in error_handler\n\n  File \"/usr/local/lib/python3.11/dist-packages/keras/src/layers/layer.py\", line 899, in __call__\n\n  File \"/usr/local/lib/python3.11/dist-packages/keras/src/utils/traceback_utils.py\", line 117, in error_handler\n\n  File \"/usr/local/lib/python3.11/dist-packages/keras/src/ops/operation.py\", line 46, in __call__\n\n  File \"/usr/local/lib/python3.11/dist-packages/keras/src/utils/traceback_utils.py\", line 156, in error_handler\n\n  File \"/usr/local/lib/python3.11/dist-packages/keras/src/models/sequential.py\", line 213, in call\n\n  File \"/usr/local/lib/python3.11/dist-packages/keras/src/models/functional.py\", line 182, in call\n\n  File \"/usr/local/lib/python3.11/dist-packages/keras/src/ops/function.py\", line 171, in _run_through_graph\n\n  File \"/usr/local/lib/python3.11/dist-packages/keras/src/models/functional.py\", line 632, in call\n\n  File \"/usr/local/lib/python3.11/dist-packages/keras/src/utils/traceback_utils.py\", line 117, in error_handler\n\n  File \"/usr/local/lib/python3.11/dist-packages/keras/src/layers/layer.py\", line 899, in __call__\n\n  File \"/usr/local/lib/python3.11/dist-packages/keras/src/utils/traceback_utils.py\", line 117, in error_handler\n\n  File \"/usr/local/lib/python3.11/dist-packages/keras/src/ops/operation.py\", line 46, in __call__\n\n  File \"/usr/local/lib/python3.11/dist-packages/keras/src/utils/traceback_utils.py\", line 156, in error_handler\n\n  File \"/usr/local/lib/python3.11/dist-packages/keras/src/layers/rnn/lstm.py\", line 570, in call\n\n  File \"/usr/local/lib/python3.11/dist-packages/keras/src/layers/rnn/rnn.py\", line 402, in call\n\n  File \"/usr/local/lib/python3.11/dist-packages/keras/src/layers/rnn/lstm.py\", line 537, in inner_loop\n\n  File \"/usr/local/lib/python3.11/dist-packages/keras/src/backend/tensorflow/rnn.py\", line 841, in lstm\n\n  File \"/usr/local/lib/python3.11/dist-packages/keras/src/backend/tensorflow/rnn.py\", line 933, in _cudnn_lstm\n\nDnn is not supported\n\t [[{{node CPU_LSTM_1/lstm_14_1/CudnnRNNV3}}]] [Op:__inference_multi_step_on_iterator_16377]",
     "output_type": "error",
     "traceback": [
      "\u001b[0;31m---------------------------------------------------------------------------\u001b[0m",
      "\u001b[0;31mInvalidArgumentError\u001b[0m                      Traceback (most recent call last)",
      "Cell \u001b[0;32mIn[39], line 2\u001b[0m\n\u001b[1;32m      1\u001b[0m \u001b[38;5;66;03m# 모델 학습\u001b[39;00m\n\u001b[0;32m----> 2\u001b[0m history \u001b[38;5;241m=\u001b[39m \u001b[43mmodel\u001b[49m\u001b[38;5;241;43m.\u001b[39;49m\u001b[43mfit\u001b[49m\u001b[43m(\u001b[49m\u001b[43mx_train\u001b[49m\u001b[43m,\u001b[49m\u001b[43m \u001b[49m\u001b[43mt_train\u001b[49m\u001b[43m,\u001b[49m\u001b[43m \u001b[49m\u001b[43mepochs\u001b[49m\u001b[38;5;241;43m=\u001b[39;49m\u001b[38;5;241;43m50\u001b[39;49m\u001b[43m,\u001b[49m\u001b[43m \u001b[49m\u001b[43mbatch_size\u001b[49m\u001b[38;5;241;43m=\u001b[39;49m\u001b[38;5;241;43m32\u001b[39;49m\u001b[43m,\u001b[49m\u001b[43m \u001b[49m\u001b[43mvalidation_data\u001b[49m\u001b[38;5;241;43m=\u001b[39;49m\u001b[43m(\u001b[49m\u001b[43mx_test\u001b[49m\u001b[43m,\u001b[49m\u001b[43m \u001b[49m\u001b[43mt_test\u001b[49m\u001b[43m)\u001b[49m\u001b[43m,\u001b[49m\u001b[43m \u001b[49m\u001b[43mverbose\u001b[49m\u001b[38;5;241;43m=\u001b[39;49m\u001b[38;5;241;43m1\u001b[39;49m\u001b[43m)\u001b[49m\n",
      "File \u001b[0;32m/usr/local/lib/python3.11/dist-packages/keras/src/utils/traceback_utils.py:122\u001b[0m, in \u001b[0;36mfilter_traceback.<locals>.error_handler\u001b[0;34m(*args, **kwargs)\u001b[0m\n\u001b[1;32m    119\u001b[0m     filtered_tb \u001b[38;5;241m=\u001b[39m _process_traceback_frames(e\u001b[38;5;241m.\u001b[39m__traceback__)\n\u001b[1;32m    120\u001b[0m     \u001b[38;5;66;03m# To get the full stack trace, call:\u001b[39;00m\n\u001b[1;32m    121\u001b[0m     \u001b[38;5;66;03m# `keras.config.disable_traceback_filtering()`\u001b[39;00m\n\u001b[0;32m--> 122\u001b[0m     \u001b[38;5;28;01mraise\u001b[39;00m e\u001b[38;5;241m.\u001b[39mwith_traceback(filtered_tb) \u001b[38;5;28;01mfrom\u001b[39;00m \u001b[38;5;28;01mNone\u001b[39;00m\n\u001b[1;32m    123\u001b[0m \u001b[38;5;28;01mfinally\u001b[39;00m:\n\u001b[1;32m    124\u001b[0m     \u001b[38;5;28;01mdel\u001b[39;00m filtered_tb\n",
      "File \u001b[0;32m/usr/local/lib/python3.11/dist-packages/tensorflow/python/eager/execute.py:53\u001b[0m, in \u001b[0;36mquick_execute\u001b[0;34m(op_name, num_outputs, inputs, attrs, ctx, name)\u001b[0m\n\u001b[1;32m     51\u001b[0m \u001b[38;5;28;01mtry\u001b[39;00m:\n\u001b[1;32m     52\u001b[0m   ctx\u001b[38;5;241m.\u001b[39mensure_initialized()\n\u001b[0;32m---> 53\u001b[0m   tensors \u001b[38;5;241m=\u001b[39m pywrap_tfe\u001b[38;5;241m.\u001b[39mTFE_Py_Execute(ctx\u001b[38;5;241m.\u001b[39m_handle, device_name, op_name,\n\u001b[1;32m     54\u001b[0m                                       inputs, attrs, num_outputs)\n\u001b[1;32m     55\u001b[0m \u001b[38;5;28;01mexcept\u001b[39;00m core\u001b[38;5;241m.\u001b[39m_NotOkStatusException \u001b[38;5;28;01mas\u001b[39;00m e:\n\u001b[1;32m     56\u001b[0m   \u001b[38;5;28;01mif\u001b[39;00m name \u001b[38;5;129;01mis\u001b[39;00m \u001b[38;5;129;01mnot\u001b[39;00m \u001b[38;5;28;01mNone\u001b[39;00m:\n",
      "\u001b[0;31mInvalidArgumentError\u001b[0m: Graph execution error:\n\nDetected at node CPU_LSTM_1/lstm_14_1/CudnnRNNV3 defined at (most recent call last):\n  File \"/usr/lib/python3.11/runpy.py\", line 198, in _run_module_as_main\n\n  File \"/usr/lib/python3.11/runpy.py\", line 88, in _run_code\n\n  File \"/usr/local/lib/python3.11/dist-packages/ipykernel_launcher.py\", line 18, in <module>\n\n  File \"/usr/local/lib/python3.11/dist-packages/traitlets/config/application.py\", line 1075, in launch_instance\n\n  File \"/usr/local/lib/python3.11/dist-packages/ipykernel/kernelapp.py\", line 739, in start\n\n  File \"/usr/local/lib/python3.11/dist-packages/tornado/platform/asyncio.py\", line 205, in start\n\n  File \"/usr/lib/python3.11/asyncio/base_events.py\", line 604, in run_forever\n\n  File \"/usr/lib/python3.11/asyncio/base_events.py\", line 1909, in _run_once\n\n  File \"/usr/lib/python3.11/asyncio/events.py\", line 80, in _run\n\n  File \"/usr/local/lib/python3.11/dist-packages/ipykernel/kernelbase.py\", line 545, in dispatch_queue\n\n  File \"/usr/local/lib/python3.11/dist-packages/ipykernel/kernelbase.py\", line 534, in process_one\n\n  File \"/usr/local/lib/python3.11/dist-packages/ipykernel/kernelbase.py\", line 437, in dispatch_shell\n\n  File \"/usr/local/lib/python3.11/dist-packages/ipykernel/ipkernel.py\", line 362, in execute_request\n\n  File \"/usr/local/lib/python3.11/dist-packages/ipykernel/kernelbase.py\", line 778, in execute_request\n\n  File \"/usr/local/lib/python3.11/dist-packages/ipykernel/ipkernel.py\", line 449, in do_execute\n\n  File \"/usr/local/lib/python3.11/dist-packages/ipykernel/zmqshell.py\", line 549, in run_cell\n\n  File \"/usr/local/lib/python3.11/dist-packages/IPython/core/interactiveshell.py\", line 3075, in run_cell\n\n  File \"/usr/local/lib/python3.11/dist-packages/IPython/core/interactiveshell.py\", line 3130, in _run_cell\n\n  File \"/usr/local/lib/python3.11/dist-packages/IPython/core/async_helpers.py\", line 128, in _pseudo_sync_runner\n\n  File \"/usr/local/lib/python3.11/dist-packages/IPython/core/interactiveshell.py\", line 3334, in run_cell_async\n\n  File \"/usr/local/lib/python3.11/dist-packages/IPython/core/interactiveshell.py\", line 3517, in run_ast_nodes\n\n  File \"/usr/local/lib/python3.11/dist-packages/IPython/core/interactiveshell.py\", line 3577, in run_code\n\n  File \"/tmp/ipykernel_56249/2685093025.py\", line 2, in <module>\n\n  File \"/usr/local/lib/python3.11/dist-packages/keras/src/utils/traceback_utils.py\", line 117, in error_handler\n\n  File \"/usr/local/lib/python3.11/dist-packages/keras/src/backend/tensorflow/trainer.py\", line 368, in fit\n\n  File \"/usr/local/lib/python3.11/dist-packages/keras/src/backend/tensorflow/trainer.py\", line 216, in function\n\n  File \"/usr/local/lib/python3.11/dist-packages/keras/src/backend/tensorflow/trainer.py\", line 129, in multi_step_on_iterator\n\n  File \"/usr/local/lib/python3.11/dist-packages/keras/src/backend/tensorflow/trainer.py\", line 110, in one_step_on_data\n\n  File \"/usr/local/lib/python3.11/dist-packages/keras/src/backend/tensorflow/trainer.py\", line 56, in train_step\n\n  File \"/usr/local/lib/python3.11/dist-packages/keras/src/utils/traceback_utils.py\", line 117, in error_handler\n\n  File \"/usr/local/lib/python3.11/dist-packages/keras/src/layers/layer.py\", line 899, in __call__\n\n  File \"/usr/local/lib/python3.11/dist-packages/keras/src/utils/traceback_utils.py\", line 117, in error_handler\n\n  File \"/usr/local/lib/python3.11/dist-packages/keras/src/ops/operation.py\", line 46, in __call__\n\n  File \"/usr/local/lib/python3.11/dist-packages/keras/src/utils/traceback_utils.py\", line 156, in error_handler\n\n  File \"/usr/local/lib/python3.11/dist-packages/keras/src/models/sequential.py\", line 213, in call\n\n  File \"/usr/local/lib/python3.11/dist-packages/keras/src/models/functional.py\", line 182, in call\n\n  File \"/usr/local/lib/python3.11/dist-packages/keras/src/ops/function.py\", line 171, in _run_through_graph\n\n  File \"/usr/local/lib/python3.11/dist-packages/keras/src/models/functional.py\", line 632, in call\n\n  File \"/usr/local/lib/python3.11/dist-packages/keras/src/utils/traceback_utils.py\", line 117, in error_handler\n\n  File \"/usr/local/lib/python3.11/dist-packages/keras/src/layers/layer.py\", line 899, in __call__\n\n  File \"/usr/local/lib/python3.11/dist-packages/keras/src/utils/traceback_utils.py\", line 117, in error_handler\n\n  File \"/usr/local/lib/python3.11/dist-packages/keras/src/ops/operation.py\", line 46, in __call__\n\n  File \"/usr/local/lib/python3.11/dist-packages/keras/src/utils/traceback_utils.py\", line 156, in error_handler\n\n  File \"/usr/local/lib/python3.11/dist-packages/keras/src/layers/rnn/lstm.py\", line 570, in call\n\n  File \"/usr/local/lib/python3.11/dist-packages/keras/src/layers/rnn/rnn.py\", line 402, in call\n\n  File \"/usr/local/lib/python3.11/dist-packages/keras/src/layers/rnn/lstm.py\", line 537, in inner_loop\n\n  File \"/usr/local/lib/python3.11/dist-packages/keras/src/backend/tensorflow/rnn.py\", line 841, in lstm\n\n  File \"/usr/local/lib/python3.11/dist-packages/keras/src/backend/tensorflow/rnn.py\", line 933, in _cudnn_lstm\n\nDnn is not supported\n\t [[{{node CPU_LSTM_1/lstm_14_1/CudnnRNNV3}}]] [Op:__inference_multi_step_on_iterator_16377]"
     ]
    }
   ],
   "source": [
    "# 모델 학습\n",
    "history = model.fit(x_train, t_train, epochs=50, batch_size=32, validation_data=(x_test, t_test), verbose=1)"
   ]
  },
  {
   "cell_type": "code",
   "execution_count": 40,
   "id": "6d63b122-74de-4149-8084-0b5db05c2b55",
   "metadata": {},
   "outputs": [
    {
     "name": "stdout",
     "output_type": "stream",
     "text": [
      "/usr/bin/python3\n"
     ]
    }
   ],
   "source": [
    "import sys\n",
    "print(sys.executable)"
   ]
  },
  {
   "cell_type": "code",
   "execution_count": 42,
   "id": "7aea38ca-d1cc-4075-a0d7-128ac74a8115",
   "metadata": {},
   "outputs": [
    {
     "name": "stdout",
     "output_type": "stream",
     "text": [
      "Name: tensorflow\n",
      "Version: 2.13.0\n",
      "Summary: TensorFlow is an open source machine learning framework for everyone.\n",
      "Home-page: https://www.tensorflow.org/\n",
      "Author: Google Inc.\n",
      "Author-email: packages@tensorflow.org\n",
      "License: Apache 2.0\n",
      "Location: /usr/local/lib/python3.11/dist-packages\n",
      "Requires: absl-py, astunparse, flatbuffers, gast, google-pasta, grpcio, h5py, keras, libclang, numpy, opt-einsum, packaging, protobuf, setuptools, six, tensorboard, tensorflow-estimator, tensorflow-io-gcs-filesystem, termcolor, typing-extensions, wrapt\n",
      "Required-by: tf_keras\n",
      "Note: you may need to restart the kernel to use updated packages.\n"
     ]
    }
   ],
   "source": [
    "pip show tensorflow"
   ]
  },
  {
   "cell_type": "code",
   "execution_count": 43,
   "id": "fa34990e-8a98-42ef-997f-2c84f3938d09",
   "metadata": {},
   "outputs": [
    {
     "name": "stdout",
     "output_type": "stream",
     "text": [
      "Requirement already satisfied: tensorflow in /usr/local/lib/python3.11/dist-packages (2.13.0)\n",
      "Requirement already satisfied: absl-py>=1.0.0 in /usr/local/lib/python3.11/dist-packages (from tensorflow) (2.1.0)\n",
      "Requirement already satisfied: astunparse>=1.6.0 in /usr/local/lib/python3.11/dist-packages (from tensorflow) (1.6.3)\n",
      "Requirement already satisfied: flatbuffers>=23.1.21 in /usr/local/lib/python3.11/dist-packages (from tensorflow) (24.3.25)\n",
      "Requirement already satisfied: gast<=0.4.0,>=0.2.1 in /usr/local/lib/python3.11/dist-packages (from tensorflow) (0.4.0)\n",
      "Requirement already satisfied: google-pasta>=0.1.1 in /usr/local/lib/python3.11/dist-packages (from tensorflow) (0.2.0)\n",
      "Requirement already satisfied: grpcio<2.0,>=1.24.3 in /usr/local/lib/python3.11/dist-packages (from tensorflow) (1.64.1)\n",
      "Requirement already satisfied: h5py>=2.9.0 in /usr/local/lib/python3.11/dist-packages (from tensorflow) (3.11.0)\n",
      "Requirement already satisfied: keras<2.14,>=2.13.1 in /usr/local/lib/python3.11/dist-packages (from tensorflow) (2.13.1)\n",
      "Requirement already satisfied: libclang>=13.0.0 in /usr/local/lib/python3.11/dist-packages (from tensorflow) (18.1.1)\n",
      "Requirement already satisfied: numpy<=1.24.3,>=1.22 in /usr/local/lib/python3.11/dist-packages (from tensorflow) (1.24.3)\n",
      "Requirement already satisfied: opt-einsum>=2.3.2 in /usr/local/lib/python3.11/dist-packages (from tensorflow) (3.3.0)\n",
      "Requirement already satisfied: packaging in /usr/local/lib/python3.11/dist-packages (from tensorflow) (24.1)\n",
      "Requirement already satisfied: protobuf!=4.21.0,!=4.21.1,!=4.21.2,!=4.21.3,!=4.21.4,!=4.21.5,<5.0.0dev,>=3.20.3 in /usr/local/lib/python3.11/dist-packages (from tensorflow) (4.25.3)\n",
      "Requirement already satisfied: setuptools in /usr/local/lib/python3.11/dist-packages (from tensorflow) (70.3.0)\n",
      "Requirement already satisfied: six>=1.12.0 in /usr/lib/python3/dist-packages (from tensorflow) (1.16.0)\n",
      "Requirement already satisfied: tensorboard<2.14,>=2.13 in /usr/local/lib/python3.11/dist-packages (from tensorflow) (2.13.0)\n",
      "Requirement already satisfied: tensorflow-estimator<2.14,>=2.13.0 in /usr/local/lib/python3.11/dist-packages (from tensorflow) (2.13.0)\n",
      "Requirement already satisfied: termcolor>=1.1.0 in /usr/local/lib/python3.11/dist-packages (from tensorflow) (2.4.0)\n",
      "Requirement already satisfied: typing-extensions<4.6.0,>=3.6.6 in /usr/local/lib/python3.11/dist-packages (from tensorflow) (4.5.0)\n",
      "Requirement already satisfied: wrapt>=1.11.0 in /usr/local/lib/python3.11/dist-packages (from tensorflow) (1.16.0)\n",
      "Requirement already satisfied: tensorflow-io-gcs-filesystem>=0.23.1 in /usr/local/lib/python3.11/dist-packages (from tensorflow) (0.37.1)\n",
      "Requirement already satisfied: wheel<1.0,>=0.23.0 in /usr/local/lib/python3.11/dist-packages (from astunparse>=1.6.0->tensorflow) (0.43.0)\n",
      "Requirement already satisfied: google-auth<3,>=1.6.3 in /usr/local/lib/python3.11/dist-packages (from tensorboard<2.14,>=2.13->tensorflow) (2.37.0)\n",
      "Requirement already satisfied: google-auth-oauthlib<1.1,>=0.5 in /usr/local/lib/python3.11/dist-packages (from tensorboard<2.14,>=2.13->tensorflow) (1.0.0)\n",
      "Requirement already satisfied: markdown>=2.6.8 in /usr/local/lib/python3.11/dist-packages (from tensorboard<2.14,>=2.13->tensorflow) (3.6)\n",
      "Requirement already satisfied: requests<3,>=2.21.0 in /usr/local/lib/python3.11/dist-packages (from tensorboard<2.14,>=2.13->tensorflow) (2.32.3)\n",
      "Requirement already satisfied: tensorboard-data-server<0.8.0,>=0.7.0 in /usr/local/lib/python3.11/dist-packages (from tensorboard<2.14,>=2.13->tensorflow) (0.7.2)\n",
      "Requirement already satisfied: werkzeug>=1.0.1 in /usr/local/lib/python3.11/dist-packages (from tensorboard<2.14,>=2.13->tensorflow) (3.0.3)\n",
      "Requirement already satisfied: cachetools<6.0,>=2.0.0 in /usr/local/lib/python3.11/dist-packages (from google-auth<3,>=1.6.3->tensorboard<2.14,>=2.13->tensorflow) (5.5.0)\n",
      "Requirement already satisfied: pyasn1-modules>=0.2.1 in /usr/local/lib/python3.11/dist-packages (from google-auth<3,>=1.6.3->tensorboard<2.14,>=2.13->tensorflow) (0.4.1)\n",
      "Requirement already satisfied: rsa<5,>=3.1.4 in /usr/local/lib/python3.11/dist-packages (from google-auth<3,>=1.6.3->tensorboard<2.14,>=2.13->tensorflow) (4.9)\n",
      "Requirement already satisfied: requests-oauthlib>=0.7.0 in /usr/local/lib/python3.11/dist-packages (from google-auth-oauthlib<1.1,>=0.5->tensorboard<2.14,>=2.13->tensorflow) (2.0.0)\n",
      "Requirement already satisfied: charset-normalizer<4,>=2 in /usr/local/lib/python3.11/dist-packages (from requests<3,>=2.21.0->tensorboard<2.14,>=2.13->tensorflow) (3.3.2)\n",
      "Requirement already satisfied: idna<4,>=2.5 in /usr/local/lib/python3.11/dist-packages (from requests<3,>=2.21.0->tensorboard<2.14,>=2.13->tensorflow) (3.7)\n",
      "Requirement already satisfied: urllib3<3,>=1.21.1 in /usr/local/lib/python3.11/dist-packages (from requests<3,>=2.21.0->tensorboard<2.14,>=2.13->tensorflow) (2.2.2)\n",
      "Requirement already satisfied: certifi>=2017.4.17 in /usr/local/lib/python3.11/dist-packages (from requests<3,>=2.21.0->tensorboard<2.14,>=2.13->tensorflow) (2024.7.4)\n",
      "Requirement already satisfied: MarkupSafe>=2.1.1 in /usr/local/lib/python3.11/dist-packages (from werkzeug>=1.0.1->tensorboard<2.14,>=2.13->tensorflow) (2.1.5)\n",
      "Requirement already satisfied: pyasn1<0.7.0,>=0.4.6 in /usr/local/lib/python3.11/dist-packages (from pyasn1-modules>=0.2.1->google-auth<3,>=1.6.3->tensorboard<2.14,>=2.13->tensorflow) (0.6.1)\n",
      "Requirement already satisfied: oauthlib>=3.0.0 in /usr/lib/python3/dist-packages (from requests-oauthlib>=0.7.0->google-auth-oauthlib<1.1,>=0.5->tensorboard<2.14,>=2.13->tensorflow) (3.2.0)\n",
      "\u001b[33mWARNING: Running pip as the 'root' user can result in broken permissions and conflicting behaviour with the system package manager, possibly rendering your system unusable.It is recommended to use a virtual environment instead: https://pip.pypa.io/warnings/venv. Use the --root-user-action option if you know what you are doing and want to suppress this warning.\u001b[0m\u001b[33m\n",
      "\u001b[0m\n",
      "\u001b[1m[\u001b[0m\u001b[34;49mnotice\u001b[0m\u001b[1;39;49m]\u001b[0m\u001b[39;49m A new release of pip is available: \u001b[0m\u001b[31;49m24.1.2\u001b[0m\u001b[39;49m -> \u001b[0m\u001b[32;49m24.3.1\u001b[0m\n",
      "\u001b[1m[\u001b[0m\u001b[34;49mnotice\u001b[0m\u001b[1;39;49m]\u001b[0m\u001b[39;49m To update, run: \u001b[0m\u001b[32;49mpython3 -m pip install --upgrade pip\u001b[0m\n",
      "Note: you may need to restart the kernel to use updated packages.\n"
     ]
    }
   ],
   "source": []
  },
  {
   "cell_type": "code",
   "execution_count": null,
   "id": "4676071e-d055-4c33-9f22-9a36c05446d8",
   "metadata": {},
   "outputs": [],
   "source": []
  }
 ],
 "metadata": {
  "kernelspec": {
   "display_name": "Python 3 (ipykernel)",
   "language": "python",
   "name": "python3"
  },
  "language_info": {
   "codemirror_mode": {
    "name": "ipython",
    "version": 3
   },
   "file_extension": ".py",
   "mimetype": "text/x-python",
   "name": "python",
   "nbconvert_exporter": "python",
   "pygments_lexer": "ipython3",
   "version": "3.11.0rc1"
  }
 },
 "nbformat": 4,
 "nbformat_minor": 5
}
